2024-01-17 12:24:05,033 INFO    StreamThr :28609 [internal.py:wandb_internal():86] W&B internal server running at pid: 28609, started at: 2024-01-17 12:24:05.033492
2024-01-17 12:24:05,034 DEBUG   HandlerThread:28609 [handler.py:handle_request():146] handle_request: status
2024-01-17 12:24:05,037 INFO    WriterThread:28609 [datastore.py:open_for_write():87] open: /home/zyk/Personal_study_projects/ECG_mit-bih/wandb/run-20240117_122405-juo7twt3/run-juo7twt3.wandb
2024-01-17 12:24:05,038 DEBUG   SenderThread:28609 [sender.py:send():382] send: header
2024-01-17 12:24:05,044 DEBUG   SenderThread:28609 [sender.py:send():382] send: run
2024-01-17 12:24:06,361 ERROR   SenderThread:28609 [internal_api.py:execute():373] 404 response executing GraphQL.
2024-01-17 12:24:06,361 ERROR   SenderThread:28609 [internal_api.py:execute():374] {"errors":[{"message":"entity 01_17 not found during upsertBucket","path":["upsertBucket"]}],"data":{"upsertBucket":null}}
2024-01-17 12:24:06,361 ERROR   SenderThread:28609 [sender.py:send_run():987] It appears that you do not have permission to access the requested resource. Please reach out to the project owner to grant you access. If you have the correct permissions, verify that there are no issues with your networking setup.(Error 404: Not Found)
Traceback (most recent call last):
  File "/home/zyk/anaconda3/envs/ecg/lib/python3.8/site-packages/wandb/sdk/lib/retry.py", line 131, in __call__
    result = self._call_fn(*args, **kwargs)
  File "/home/zyk/anaconda3/envs/ecg/lib/python3.8/site-packages/wandb/sdk/internal/internal_api.py", line 369, in execute
    return self.client.execute(*args, **kwargs)  # type: ignore
  File "/home/zyk/anaconda3/envs/ecg/lib/python3.8/site-packages/wandb/vendor/gql-0.2.0/wandb_gql/client.py", line 52, in execute
    result = self._get_result(document, *args, **kwargs)
  File "/home/zyk/anaconda3/envs/ecg/lib/python3.8/site-packages/wandb/vendor/gql-0.2.0/wandb_gql/client.py", line 60, in _get_result
    return self.transport.execute(document, *args, **kwargs)
  File "/home/zyk/anaconda3/envs/ecg/lib/python3.8/site-packages/wandb/sdk/lib/gql_request.py", line 59, in execute
    request.raise_for_status()
  File "/home/zyk/anaconda3/envs/ecg/lib/python3.8/site-packages/requests/models.py", line 1021, in raise_for_status
    raise HTTPError(http_error_msg, response=self)
requests.exceptions.HTTPError: 404 Client Error: Not Found for url: https://api.wandb.ai/graphql

During handling of the above exception, another exception occurred:

Traceback (most recent call last):
  File "/home/zyk/anaconda3/envs/ecg/lib/python3.8/site-packages/wandb/sdk/internal/sender.py", line 985, in send_run
    self._init_run(run, config_value_dict)
  File "/home/zyk/anaconda3/envs/ecg/lib/python3.8/site-packages/wandb/sdk/internal/sender.py", line 1027, in _init_run
    server_run, inserted, server_messages = self._api.upsert_run(
  File "/home/zyk/anaconda3/envs/ecg/lib/python3.8/site-packages/wandb/apis/normalize.py", line 73, in wrapper
    raise err
  File "/home/zyk/anaconda3/envs/ecg/lib/python3.8/site-packages/wandb/apis/normalize.py", line 41, in wrapper
    return func(*args, **kwargs)
  File "/home/zyk/anaconda3/envs/ecg/lib/python3.8/site-packages/wandb/sdk/internal/internal_api.py", line 2216, in upsert_run
    response = self.gql(
  File "/home/zyk/anaconda3/envs/ecg/lib/python3.8/site-packages/wandb/sdk/internal/internal_api.py", line 341, in gql
    ret = self._retry_gql(
  File "/home/zyk/anaconda3/envs/ecg/lib/python3.8/site-packages/wandb/sdk/lib/retry.py", line 147, in __call__
    retry_timedelta_triggered = check_retry_fn(e)
  File "/home/zyk/anaconda3/envs/ecg/lib/python3.8/site-packages/wandb/util.py", line 965, in check_retry_fn
    return fallback_retry_fn(e)
  File "/home/zyk/anaconda3/envs/ecg/lib/python3.8/site-packages/wandb/util.py", line 907, in no_retry_auth
    raise CommError(
wandb.errors.CommError: It appears that you do not have permission to access the requested resource. Please reach out to the project owner to grant you access. If you have the correct permissions, verify that there are no issues with your networking setup.(Error 404: Not Found)
2024-01-17 12:24:07,431 DEBUG   HandlerThread:28609 [handler.py:handle_request():146] handle_request: shutdown
2024-01-17 12:24:07,431 INFO    HandlerThread:28609 [handler.py:finish():869] shutting down handler
2024-01-17 12:24:08,044 INFO    WriterThread:28609 [datastore.py:close():296] close: /home/zyk/Personal_study_projects/ECG_mit-bih/wandb/run-20240117_122405-juo7twt3/run-juo7twt3.wandb
2024-01-17 12:24:08,363 INFO    SenderThread:28609 [sender.py:finish():1572] shutting down sender
