Traceback (most recent call last):
  File "/home/zyk/anaconda3/envs/ecg/lib/python3.8/site-packages/wandb/sdk/wandb_config.py", line 162, in __getattr__
    return self.__getitem__(key)
  File "/home/zyk/anaconda3/envs/ecg/lib/python3.8/site-packages/wandb/sdk/wandb_config.py", line 130, in __getitem__
    return self._items[key]
KeyError: 'Voltage_Partitions'
The above exception was the direct cause of the following exception:
Traceback (most recent call last):
  File "/home/zyk/Personal_study_projects/ECG_mit-bih/main.py", line 27, in train
    dataset = ECGDataset(X_data, Y_data, training_params["Num_Datas"], config.Time_Partitions, config.Voltage_Partitions)
  File "/home/zyk/anaconda3/envs/ecg/lib/python3.8/site-packages/wandb/sdk/wandb_config.py", line 164, in __getattr__
    raise AttributeError(
AttributeError: <class 'wandb.sdk.wandb_config.Config'> object has no attribute 'Voltage_Partitions'